<?xml version="1.0"?>
 <robot name="willy">
    
    <link name="base_footprint"/> 

    <link name="base_link">     
        <visual name="">
            <geometry><box size="1.6 0.76 0.6"/></geometry>
            <origin xyz="0.0 0.0 0.0" rpy="0.0 0.0 0.0"/>
            <material name="silver"><color rgba="0 0.27 0.52 1.0"/></material>
        </visual>        
    </link>
    
    <joint name="base_link_to_base_footprint" type="fixed">
        <parent link="base_footprint"/>
        <child  link="base_link"/>
        <origin xyz="0 0 0.6" rpy="0 0 0"/>
   </joint> 
    

<!-- laser -->
 <link name="laser">
    <visual name="">
        <geometry>  <cylinder radius="0.1" length="0.1"/> </geometry>
        <origin xyz="0.0 0 0.0" rpy="0.0 0.0 0.0"/>
        <material name="black">  <color rgba="0.0 0.0 0.0 1.0"/>  </material>
    </visual>
    
 </link>

 <joint name="laser_joint" type="fixed">
        <origin xyz="0.50 0 0.3" rpy="0 0.0 0.0"/>  
        <parent link="base_link"/>
        <child link="laser"/>
 </joint>

 <!-- laser1 -->
<!-- 
  <link name="laser1">
    <visual name="">
        <geometry>  <cylinder radius="0.1" length="0.1"/> </geometry>
        <origin xyz="0.0 0 0.0" rpy="0.0 0.0 0.0"/>
        <material name="black">  <color rgba="0.0 0.0 0.0 1.0"/>  </material>
    </visual>
    
 </link>

 <joint name="laser1_joint" type="fixed">
        <origin xyz="0.50 0 0.3" rpy="0 0.0 0.0"/>  
        <parent link="base_link"/>
        <child link="laser1"/>
 </joint> -->

<!-- Front Right Wheel -->
<link name="wheel_right_front_link">
    <inertial>
        <origin xyz="0.0 0.0 0.0" rpy="0.0 0.0 0.0"/>
        <mass value="0.0"/>
        <inertia ixx="0.0" ixy="0.0" ixz="0.0" iyy="0.0" iyz="0.0" izz="0.0"/>
    </inertial>
    <visual name="">
        <origin xyz="0.0 0 0.0" rpy="0.0 0.0 0.0"/>
        <geometry>
            <cylinder radius="0.15" length="0.1"/>
        </geometry>

 <material name="black">
            <color rgba="0.0 0.0 0.0 1.0"/>
            <texture filename=""/>
        </material>
    </visual>
    <collision>
        <origin xyz="0.0 0.0 0.0" rpy="0.0 0.0 0.0"/>
        <geometry>
            <box size="0.0 0.0 0.0"/>
        </geometry>
    </collision>
</link>

<joint name="wheel_right_front_joint" type="continuous">
    <origin xyz="0.5 0.5 -0.45" rpy="1.57 0.0 0.0"/>
    <parent link="base_link"/>
    <child link="wheel_right_front_link"/>
    <axis xyz="1.0 0.0 0.0"/>
    <limit lower="0.0" upper="0.0" effort="0.0" velocity="0.0"/>
</joint>

<!-- Front left Wheel -->
<link name="wheel_left_front_link">
    <inertial>
        <origin xyz="0.0 0.0 0.0" rpy="0.0 0.0 0.0"/>
        <mass value="0.0"/>
        <inertia ixx="0.0" ixy="0.0" ixz="0.0" iyy="0.0" iyz="0.0" izz="0.0"/>
    </inertial>
    <visual name="">
        <origin xyz="0.0 0 0.0" rpy="0.0 0.0 0.0"/>
        <geometry>
            <cylinder radius="0.15" length="0.1"/>
        </geometry>

 <material name="black">
            <color rgba="0.0 0.0 0.0 1.0"/>
            <texture filename=""/>
        </material>
    </visual>
    <collision>
        <origin xyz="0.0 0.0 0.0" rpy="0.0 0.0 0.0"/>
        <geometry>
            <box size="0.0 0.0 0.0"/>
        </geometry>
    </collision>
</link>

<joint name="wheel_left_front_joint" type="continuous">
    <origin xyz="0.5 -0.5 -0.45" rpy="1.57 0.0 0.0"/>
    <parent link="base_link"/>
    <child link="wheel_left_front_link"/>
    <axis xyz="1.0 0.0 0.0"/>
    <limit lower="0.0" upper="0.0" effort="0.0" velocity="0.0"/>
</joint>




<!-- Rear Right Wheel -->
<link name="wheel_right_rear_link">
    <inertial>
        <origin xyz="0.0 0.0 0.0" rpy="0.0 0.0 0.0"/>
        <mass value="0.0"/>
        <inertia ixx="0.0" ixy="0.0" ixz="0.0" iyy="0.0" iyz="0.0" izz="0.0"/>
    </inertial>
    <visual name="">
        <origin xyz="0.0 0 0.0" rpy="0.0 0.0 0.0"/>
        <geometry>
            <cylinder radius="0.15" length="0.1"/>
        </geometry>

      <material name="black">
            <color rgba="0.0 0.0 0.0 1.0"/>
            <texture filename=""/>
        </material>
    </visual>
    <collision>
        <origin xyz="0.0 0.0 0.0" rpy="0.0 0.0 0.0"/>
        <geometry>
            <box size="0.0 0.0 0.0"/>
        </geometry>
    </collision>
</link>

<joint name="wheel_right_rear_joint" type="continuous">
    <origin xyz="-0.5 0.5 -0.45" rpy="1.57 0.0 0.0"/>
    <parent link="base_link"/>
    <child link="wheel_right_rear_link"/>
    <axis xyz="1.0 0.0 0.0"/>
    <limit lower="0.0" upper="0.0" effort="0.0" velocity="0.0"/>
</joint>

<!-- Rear Left Wheel -->
<link name="wheel_left_rear_link">
    <inertial>
        <origin xyz="0.0 0.0 0.0" rpy="0.0 0.0 0.0"/>
        <mass value="0.0"/>
        <inertia ixx="0.0" ixy="0.0" ixz="0.0" iyy="0.0" iyz="0.0" izz="0.0"/>
    </inertial>
    <visual name="">
        <origin xyz="0.0 0 0.0" rpy="0.0 0.0 0.0"/>
        <geometry>
            <cylinder radius="0.15" length="0.1"/>
        </geometry>

        <material name="black">
            <color rgba="0.0 0.0 0.0 1.0"/>
            <texture filename=""/>
        </material>
    </visual>
    <collision>
        <origin xyz="0.0 0.0 0.0" rpy="0.0 0.0 0.0"/>
        <geometry>
            <box size="0.0 0.0 0.0"/>
        </geometry>
    </collision>
</link>

<joint name="wheel_left_rear_joint" type="continuous">
    <origin xyz="-0.5 -0.5 -0.45" rpy="1.57 0.0 0.0"/>
    <parent link="base_link"/>
    <child link="wheel_left_rear_link"/>
    <axis xyz="1.0 0.0 0.0"/>
    <limit lower="0.0" upper="0.0" effort="0.0" velocity="0.0"/>
</joint>

<!-- Middle Left Wheel -->
<link name="wheel_left_middle_link">
    <inertial>
        <origin xyz="0.0 0.0 0.0" rpy="0.0 0.0 0.0"/>
        <mass value="0.0"/>
        <inertia ixx="0.0" ixy="0.0" ixz="0.0" iyy="0.0" iyz="0.0" izz="0.0"/>
    </inertial>
    <visual name="">
        <origin xyz="0.0 0 0.0" rpy="0.0 0.0 0.0"/>
        <geometry>
            <cylinder radius="0.15" length="0.1"/>
        </geometry>

        <material name="black">
            <color rgba="0.0 0.0 0.0 1.0"/>
            <texture filename=""/>
        </material>
    </visual>
    <collision>
        <origin xyz="0.0 0.0 0.0" rpy="0.0 0.0 0.0"/>
        <geometry>
            <box size="0.0 0.0 0.0"/>
        </geometry>
    </collision>
</link>

<joint name="wheel_left_middle_joint" type="continuous">
    <origin xyz="0 -0.5 -0.45" rpy="1.57 0.0 0.0"/>
    <parent link="base_link"/>
    <child link="wheel_left_middle_link"/>
    <axis xyz="1.0 0.0 0.0"/>
    <limit lower="0.0" upper="0.0" effort="0.0" velocity="0.0"/>
</joint>

<!-- Middle Right Wheel -->
<link name="wheel_right_middle_link">
    <inertial>
        <origin xyz="0.0 0.0 0.0" rpy="0.0 0.0 0.0"/>
        <mass value="0.0"/>
        <inertia ixx="0.0" ixy="0.0" ixz="0.0" iyy="0.0" iyz="0.0" izz="0.0"/>
    </inertial>
    <visual name="">
        <origin xyz="0.0 0 0.0" rpy="0.0 0.0 0.0"/>
        <geometry>
            <cylinder radius="0.15" length="0.1"/>
        </geometry>

        <material name="black">
            <color rgba="0.0 0.0 0.0 1.0"/>
            <texture filename=""/>
        </material>
    </visual>
    <collision>
        <origin xyz="0.0 0.0 0.0" rpy="0.0 0.0 0.0"/>
        <geometry>
            <box size="0.0 0.0 0.0"/>
        </geometry>
    </collision>
</link>

<joint name="wheel_right_middle_joint" type="continuous">
    <origin xyz="0 0.5 -0.45" rpy="1.57 0.0 0.0"/>
    <parent link="base_link"/>
    <child link="wheel_right_middle_link"/>
    <axis xyz="1.0 0.0 0.0"/>
    <limit lower="0.0" upper="0.0" effort="0.0" velocity="0.0"/>
</joint>


</robot>